<?xml version="1.0" ?>
<!-- =================================================================================== -->
<!-- |    This document was autogenerated by xacro from src/robot_description/urdf/robot.urdf.xacro | -->
<!-- |    EDITING THIS FILE BY HAND IS NOT RECOMMENDED                                 | -->
<!-- =================================================================================== -->
<robot name="monRobot" xmlns:xacro="http://ros.org/wiki/xacro">
  <gazebo reference="chassis">
    <material>Gazebo/DarkGrey</material>
  </gazebo>
  <gazebo reference="left_wheel">
    <mu1>1.2</mu1>
    <mu2>1.2</mu2>
    <kp>500000.0</kp>
    <kd>10.0</kd>
    <minDepth>0.001</minDepth>
    <maxVel>0.1</maxVel>
    <material>Gazebo/FlatBlack</material>
  </gazebo>
  <gazebo reference="right_wheel">
    <mu1>1.2</mu1>
    <mu2>1.2</mu2>
    <kp>500000.0</kp>
    <kd>10.0</kd>
    <minDepth>0.001</minDepth>
    <maxVel>0.1</maxVel>
    <material>Gazebo/FlatBlack</material>
  </gazebo>
  <gazebo reference="caster">
    <mu1>0.1</mu1>
    <mu2>0.1</mu2>
    <kp>1000000.0</kp>
    <kd>100.0</kd>
    <minDepth>0.001</minDepth>
    <maxVel>1.0</maxVel>
    <material>Gazebo/FlatBlack</material>
  </gazebo>
  <link name="base_link"/>
  <!-- permet d'utiliser Move Base -->
  <joint name="base_joint" type="fixed">
    <parent link="base_link"/>
    <child link="chassis"/>
    <origin rpy="0 0 0" xyz="0 0 0.01"/>
  </joint>
  <link name="chassis">
    <collision>
      <origin rpy="0 0 0" xyz="0 0 .1"/>
      <geometry>
        <box size="0.4 0.2 0.1"/>
      </geometry>
    </collision>
    <visual>
      <origin rpy="0 0 0" xyz="0 0 .1"/>
      <geometry>
        <box size="0.4 0.2 0.1"/>
      </geometry>
    </visual>
    <inertial>
      <mass value="2.0"/>
      <inertia ixx="0.01" ixy="0.0" ixz="0.0" iyy="0.01" iyz="0.0" izz="0.01"/>
    </inertial>
  </link>
  <link name="caster">
    <collision>
      <geometry>
        <sphere radius="0.05"/>
      </geometry>
    </collision>
    <visual>
      <geometry>
        <sphere radius="0.05"/>
      </geometry>
    </visual>
    <inertial>
      <mass value="0.01"/>
      <inertia ixx="0.01" ixy="0.0" ixz="0.0" iyy="0.01" iyz="0.0" izz="0.01"/>
    </inertial>
  </link>
  <joint name="caster_to_chassis" type="fixed">
    <origin rpy="0 0 0" xyz="-0.15 0 0.05"/>
    <child link="caster"/>
    <parent link="chassis"/>
  </joint>
  <link name="left_wheel">
    <collision>
      <origin rpy="0 1.5707 1.5707" xyz="0 0 0"/>
      <geometry>
        <cylinder length="0.05" radius="0.1"/>
      </geometry>
    </collision>
    <visual>
      <origin rpy="0 1.5707 1.5707" xyz="0 0 0"/>
      <geometry>
        <cylinder length="0.05" radius="0.1"/>
      </geometry>
    </visual>
    <inertial>
      <mass value="0.3"/>
      <inertia ixx="0.01" ixy="0.0" ixz="0.0" iyy="0.01" iyz="0.0" izz="0.01"/>
    </inertial>
  </link>
  <link name="right_wheel">
    <collision>
      <origin rpy="0 1.5707 1.5707" xyz="0 0 0"/>
      <geometry>
        <cylinder length="0.05" radius="0.1"/>
      </geometry>
    </collision>
    <visual>
      <origin rpy="0 1.5707 1.5707" xyz="0 0 0"/>
      <geometry>
        <cylinder length="0.05" radius="0.1"/>
      </geometry>
    </visual>
    <inertial>
      <mass value="0.3"/>
      <inertia ixx="0.01" ixy="0.0" ixz="0.0" iyy="0.01" iyz="0.0" izz="0.01"/>
    </inertial>
  </link>
  <joint name="left_wheel_hinge" type="continuous">
    <origin rpy="0 0 0" xyz="0.1 0.13 0.1"/>
    <child link="left_wheel"/>
    <parent link="chassis"/>
    <axis xyz="0 1 0"/>
  </joint>
  <joint name="right_wheel_hinge" type="continuous">
    <origin rpy="0 0 0" xyz="0.1 -0.13 0.1"/>
    <child link="right_wheel"/>
    <parent link="chassis"/>
    <axis xyz="0 1 0"/>
  </joint>
  <joint name="hokuyo_joint" type="fixed">
    <axis xyz="0 1 0"/>
    <origin rpy="0 0 0" xyz="0 0 0.2"/>
    <parent link="chassis"/>
    <child link="hokuyo_link"/>
  </joint>
  <!-- Hokuyo Laser -->
  <link name="hokuyo_link">
    <collision>
      <origin rpy="0 0 0" xyz="0 0 0"/>
      <geometry>
        <box size="0.1 0.1 0.1"/>
      </geometry>
    </collision>
    <visual>
      <origin rpy="0 0 0" xyz="0 0 0"/>
      <geometry>
        <sphere radius="0.1"/>
      </geometry>
    </visual>
    <inertial>
      <mass value="1e-5"/>
      <origin rpy="0 0 0" xyz="0 0 0"/>
      <inertia ixx="1e-6" ixy="0" ixz="0" iyy="1e-6" iyz="0" izz="1e-6"/>
    </inertial>
  </link>
  <!-- hokuyo -->
  <gazebo reference="hokuyo_link">
    <sensor name="head_hokuyo_sensor" type="ray">
      <pose>0 0 0 0 0 0</pose>
      <visualize>true</visualize>
      <update_rate>2</update_rate>
      <ray>
        <scan>
          <horizontal>
            <samples>720</samples>
            <resolution>1</resolution>
            <min_angle>-3.1415</min_angle>
            <max_angle>3.1415</max_angle>
          </horizontal>
        </scan>
        <range>
          <min>0.10</min>
          <max>30.0</max>
          <resolution>0.01</resolution>
        </range>
        <noise>
          <type>gaussian</type>
          <!-- Noise parameters based on published spec for Hokuyo laser
               achieving "+-30mm" accuracy at range < 10m.  A mean of 0.0m and
               stddev of 0.01m will put 99.7% of samples within 0.03m of the true
               reading. -->
          <mean>0.0</mean>
          <stddev>0.01</stddev>
        </noise>
      </ray>
      <plugin filename="libgazebo_ros_laser.so" name="gazebo_ros_head_hokuyo_controller">
        <topicName>/scan</topicName>
        <frameName>hokuyo_link</frameName>
      </plugin>
    </sensor>
  </gazebo>
  <!-- -->
  <joint name="camera_joint" type="fixed">
    <origin rpy="0 0 0" xyz="0.1 0 0.2"/>
    <parent link="chassis"/>
    <child link="camera_link"/>
  </joint>
  <!-- Camera -->
  <link name="camera_link">
    <collision>
      <origin rpy="0 0 0" xyz="0 0 0"/>
      <geometry>
        <box size="0.1 0.1 0.1"/>
      </geometry>
    </collision>
    <visual>
      <origin rpy="0 0 0" xyz="0 0 0"/>
      <geometry>
        <box size="0.1 0.1 0.1"/>
      </geometry>
      <material name="red"/>
    </visual>
    <inertial>
      <mass value="1e-5"/>
      <origin rpy="0 0 0" xyz="0 0 0"/>
      <inertia ixx="1e-6" ixy="0" ixz="0" iyy="1e-6" iyz="0" izz="1e-6"/>
    </inertial>
  </link>
  <!-- Size of square 'camera' box -->
  <!-- camera -->
  <gazebo reference="camera_link">
    <sensor name="camera1" type="camera">
      <update_rate>30.0</update_rate>
      <camera name="head">
        <horizontal_fov>1.3962634</horizontal_fov>
        <image>
          <width>800</width>
          <height>800</height>
          <format>R8G8B8</format>
        </image>
        <clip>
          <near>0.02</near>
          <far>300</far>
        </clip>
        <noise>
          <type>gaussian</type>
          <!-- Noise is sampled independently per pixel on each frame.
               That pixel's noise value is added to each of its color
               channels, which at that point lie in the range [0,1]. -->
          <mean>0.0</mean>
          <stddev>0.007</stddev>
        </noise>
      </camera>
      <plugin filename="libgazebo_ros_camera.so" name="camera_controller">
        <alwaysOn>true</alwaysOn>
        <updateRate>0.0</updateRate>
        <cameraName>rrbot/camera1</cameraName>
        <imageTopicName>image_raw</imageTopicName>
        <cameraInfoTopicName>camera_info</cameraInfoTopicName>
        <frameName>camera_link</frameName>
        <hackBaseline>0.07</hackBaseline>
        <distortionK1>0.0</distortionK1>
        <distortionK2>0.0</distortionK2>
        <distortionK3>0.0</distortionK3>
        <distortionT1>0.0</distortionT1>
        <distortionT2>0.0</distortionT2>
      </plugin>
    </sensor>
  </gazebo>
  <!-- Controllers -->
  <gazebo>
    <plugin filename="libgazebo_ros_diff_drive.so" name="wheels_controller">
      <commandTopic>cmd_vel</commandTopic>
      <odometryTopic>odom</odometryTopic>
      <odometryFrame>odom</odometryFrame>
      <odometrySource>world</odometrySource>
      <publishOdomTF>true</publishOdomTF>
      <!-- ENTER BASE LINK NAME -->
      <robotBaseFrame>base_link</robotBaseFrame>
      <publishWheelTF>false</publishWheelTF>
      <publishTf>true</publishTf>
      <publishWheelJointState>true</publishWheelJointState>
      <legacyMode>false</legacyMode>
      <updateRate>30</updateRate>
      <!-- ENTER LEFT JOINT NAME -->
      <leftJoint>left_wheel_hinge</leftJoint>
      <!-- ENTER RIGHT JOINT NAME -->
      <rightJoint>right_wheel_hinge</rightJoint>
      <wheelSeparation>0.31</wheelSeparation>
      <wheelDiameter>0.1</wheelDiameter>
      <wheelAcceleration>0.1</wheelAcceleration>
      <wheelTorque>10</wheelTorque>
      <rosDebugLevel>na</rosDebugLevel>
    </plugin>
  </gazebo>
</robot>

